Workbook

Sheet GALLASTEGUI
D1: AC109RC | E1: Y | F1: AE754XE
A2: DIA | B2: SALE DE | C2: LLEGA A | D2: KM REC | E2: TN COM 29 | F2: TN ESC 35 | G2: TN ESC 37,5 | H2: REMITO Nº | I2: MATERIAL | J2: KM VACIOS | K2: $
A3: 46143 | B3: BAJO DEL TORO | C3: L. NEGRA | D3: 1070 | H3: VACIO
A4: 46146 | B4: L. NEGRA | C4: SAN FERNANDO | D4: 420 | H4: 769486
A5: 46147 | B5: SAN FERNANDO | C5: IBICUY | D5: 150 | H5: VACIO
A6: 46147 | B6: IBICUY | C6: AÑELO | D6: 1430 | H6: 125232 | I6: YPF
A7: 46150 | B7: AÑELO | C7: L. NEGRA | D7: 940 | H7: VACIO
A8: 46153 | B8: L. NEGRA | C8: J. C. PAZ | D8: 390 | H8: 771149
A9: 46154 | B9: J. C. PAZ | C9: IBICUY | D9: 170 | H9: VACIO
A10: 46154 | B10: IBICUY | C10: BANDUR | D10: 1470 | H10: 12583 | I10: YPF BANDUR
A11: 46157 | B11: BANDUR | C11: L. NEGRA | D11: 950 | H11: VACIO
A12: 46158 | B12: L. NEGRA | C12: CAMPANA | D12: 420 | G12: 36.49 | H12: 621736 | I12: CLINKER
A13: 46160
A28: 46116 | B28: L. NEGRA | C28: CAMPANA | D28: 420 | G28: 36.42 | H28: 619012 | I28: CLINKER
A29: 46118 | B29: CAMPANA | C29: SIDERCA | D29: 10 | H29: VACIO
A30: 46119 | B30: SIDERCA | C30: CATAMARCA | D30: 990 | G30: 36.04 | H30: 153050 | I30: SIDERCA | K30: 1766494.1
A31: 46120 | B31: CATAMARCA | C31: CORDOBA | D31: 380 | H31: 503424 | K31: 1119388.3
A32: 46121 | B32: CORDOBA | C32: MALAGUEÑO | D32: 50 | H32: VACIO
A33: 46121 | B33: MALAGUEÑO | C33: ROSARIO | D33: 430 | H33: 303243 | I33: PIEDRA
A34: 46122 | B34: ROSARIO | C34: RAMALLO | D34: 80 | H34: VACIO
A35: 46123 | B35: RAMALLO | C35: L. NEGRA | D35: 500 | G35: 36.18 | H35: 1064632 | I35: LODO
A36: 46125 | B36: L. NEGRA | C36: DOLORES | D36: 370 | H36: 766061
A37: 46125 | B37: DOLORES | C37: L. NEGRA | D37: 370 | H37: VACIO
A38: 46126 | B38: L. NEGRA | C38: SAN EFRNANDO | D38: 420 | H38: 766275
A39: 46127 | B39: SAN FERNANDO | C39: IBICUY | D39: 150 | H39: VACIO
A40: 46127 | B40: IBICUY | C40: BAJO DEL TORO | D40: 1560 | H40: 121254 | I40: YPF TORO
A41: 46130 | B41: BAJO DEL TORO | C41: ALLEN | D41: 270 | H41: VACIO
A42: 46132 | B42: ALLEN | C42: L. NEGRA | D42: 820 | G42: 35.5 | H42: 189570 | I42: YESO LOMA
A43: 46134 | B43: L. NEGRA | C43: ZAPALA | D43: 1010 | G43: 35.29 | H43: 620124 | I43: CLINKER
A44: 46135 | B44: ZAPALA | C44: ALLEN | D44: 240 | H44: VACIO
A45: 46136 | B45: ALLEN | C45: L. NEGRA | D45: 820 | G45: 35.1 | H45: 189848 | I45: YESO LOMA
A46: 46137 | B46: L. NEGRA | C46: SAN EFRNANDO | D46: 420 | G46: 35.34 | H46: 249561 | I46: FENOMIX
A47: 46139 | B47: SAN FERNANDO | C47: IBICUY | D47: 150 | H47: VACIO
A48: 46140 | B48: IBICUY | C48: BAJO DEL TORO | D48: 1560 | H48: 121254 | I48: YPF TORO
D49: 1 A LAS 8
D51: =SUM(D21:D50) -> 11020 | G51: =AVERAGE(G21:G49) -> 35.695714 | J51: =SUM(J21:J50) -> 0 | K51: =SUM(K21:K49) -> 2885882.4
B53: -1768.41 | C53: ,
B54: -300 | C54: ADELANTO | D54: 44083
B55: 140 | C55: PEAJES
B56: 490 | C56: PEAJES
...

Sheet SCHWINDT
A2: DIA | B2: SALE DE | C2: LLEGA A | D2: KM REC | E2: TN COM 29 | F2: TN ESC 35 | G2: TN ESC 37,5 | H2: REMITO Nº | I2: MATERIAL | J2: KM VACIOS | K2: $
A3: 46142 | B3: L. NEGRA | C3: RAMALLO | D3: 500 | H3: 620592
A4: 46144 | B4: RAMALLO | C4: L. NEGRA | D4: 500 | F4: 34.33 | H4: 1068078 | I4: ESCORIA
A5: 46146 | B5: L. NEGRA | C5: ZAPALA | D5: 1010 | H5: 620763 | I5: CLINKER
A6: 46148 | B6: ZAPALA | C6: ALLEN | D6: 240 | H6: VACIO
A7: 46148 | B7: ALLEN | C7: L. NEGRA | D7: 820 | F7: 34.1 | H7: 190230 | I7: YESO LOMA
A8: 46151 | B8: L. NEGRA | C8: ZAPALA | D8: 1010 | H8: 621109 | I8: CLINKER
A9: 46153 | B9: ZAPALA | C9: ALLEN | D9: 240 | H9: VACIO
A10: 46154 | B10: ALLEN | C10: L. NEGRA | D10: 820 | F10: 34.3 | H10: 190426 | I10: YESO LOMA
A11: 46155 | B11: L. NEGRA | C11: BAHIA BLANCA | D11: 320 | F11: 35.1 | H11: 295923 | I11: PIEDRA
A12: 46157 | B12: BAHIA BLANCA | C12: BARKER | D12: 350 | H12: VACIO
A25: 46116 | B25: L. NEGRA | C25: CAMPANA | D25: 420 | F25: 35.42 | H25: 618968 | I25: CLINKER
A26: 46118 | B26: CAMPANA | C26: SIDERCA | D26: 10 | H26: VACIO
A27: 46119 | B27: CAMPANA | C27: CATAMARCA | D27: 990 | F27: 34.72 | H27: 153029 | I27: SIDERCA | K27: 1701794.6
A28: 46120 | B28: CATAMARCA | C28: CORDOBA | D28: 380 | H28: 503419 | K28: 1057200.1
A29: 46121 | B29: CORDOBA | C29: MALAGUEÑO | D29: 50 | H29: VACIO
A30: 46121 | B30: MALAGUEÑO | C30: ROSARIO | D30: 430 | F30: 34.64 | H30: 303245 | I30: PIEDRA
A31: 46122 | B31: ROSARIO | C31: RAMALLO | D31: 80 | H31: VACIO
A32: 46123 | B32: RAMALLO | C32: L. NEGRA | D32: 500 | F32: 34.28 | H32: 1064638 | I32: LODO
A33: 46095 | B33: L. NEGRA | C33: ZAPALA | D33: 1010 | F33: 34.49 | H33: 619623 | I33: CLINKER
A34: 46127 | B34: ZAPALA | C34: ALLEN | D34: 240 | H34: VACIO
A35: 46128 | B35: ALLEN | C35: L. NEGRA | D35: 820 | F35: 34 | H35: 189594 | I35: YESO LOMA
A36: 46129 | B36: L. NEGRA | C36: C. FEDERAL | D36: 380 | H36: 294009 | I36: PIEDRA
A37: 46132 | B37: C. FEDERAL | C37: IBICUY | D37: 170 | H37: VACIO
A38: 46133 | B38: IBICUY | C38: RAMALLO | D38: 230 | H38: VACIO
A39: 46133 | B39: RAMALLO | C39: L. NEGRA | D39: 500 | F39: 34.67 | H39: 1066227 | I39: ESCORIA
A40: 46134 | B40: L. NEGRA | C40: ZAPALA | D40: 1010 | F40: 35.26 | H40: 620105 | I40: CLINKER
A41: 46135 | B41: ZAPALA | C41: ALLEN | D41: 240 | H41: VACIO
A42: 46136 | B42: ALLEN | C42: L. NEGRA | D42: 820 | F42: 33.7 | H42: 189877 | I42: YESO LOMA
A43: 46140 | B43: L. NEGRA | C43: CAMPANA | D43: 420 | F43: 34.24 | H43: 620423 | I43: CLINKER
A44: 46140 | B44: CAMPANA | C44: SIDERAR | D44: 150 | H44: VACIO
A45: 46141 | B45: SIDERAR | C45: RAMALLO | D45: 10 | H45: 1067612 | I45: CORTO
A46: 46141 | B46: RAMALLO | C46: SIDERAR | D46: 10 | H46: VACIO
A47: 46141 | B47: SIDERAR | C47: RAMALLO | D47: 10 | H47: 1067646 | I47: CORTO
A48: 46141 | B48: RAMALLO | C48: SIDERAR | D48: 10 | H48: VACIO
A49: 46141 | B49: SIDERAR | C49: L. NEGRA | D49: 500 | F49: 34.21 | H49: 1067677 | I49: ESCORIA
D50: 30 A LAS 11
D52: =SUM(D3:D51) -> 15200 | F52: =AVERAGE(F3:F50) -> 34.497333 | J52: =SUM(J3:J51) -> 0 | K52: =SUM(K3:K51) -> 2758994.6
B54: -2131.06
B55: 200 | C55: PEAJES | D55: 43756
...

Sheet SAENZ BURUAGA
D1: AE169ZO
A2: DIA | B2: SALE DE | C2: LLEGA A | D2: KM REC | E2: TN COM 29 | F2: TN ESC 35 | G2: TN ESC 37,5 | H2: REMITO Nº | I2: MATERIAL | J2: KM VACIOS | K2: $
A3: 46142 | B3: DARSENA | C3: L. NEGRA | D3: 380 | H3: VACIO
A4: 46146 | B4: L. NEGRA | C4: M. DEL PLATA | D4: 320 | F4: 34.56 | H4: 769524
A5: 46147 | B5: M. DEL PLATA | C5: L. NEGRA | D5: 320 | H5: VACIO
A6: 46147 | B6: L. NEGRA | C6: OLAVARRIA | D6: 40 | F6: 34.76 | H6: 769718
A7: 46148 | B7: OLAVARRIA | C7: L. NEGRA | D7: 40 | H7: VACIO
A8: 46148 | B8: L. NEGRA | C8: SOLA | D8: 360 | F8: 35.02 | H8: 769876
A9: 46149 | B9: SOLA | C9: LOMASER | D9: 70 | H9: VACIO
A10: 46149 | B10: LOMASER | C10: RAMALLO | D10: 300 | H10: 899959
A11: 46150 | B11: RAMALLO | C11: SOLA | D11: 240 | F11: 33.18 | H11: 279964 | I11: ESCORIA
A12: 46150 | B12: SOLA | C12: LOMASER | D12: 70 | H12: VACIO
A13: 46150 | B13: LOMASER | C13: CAMPANA | D13: 125 | F13: 35.18 | H13: 900184
A14: 46151 | B14: CAMPANA | C14: RAMALLO | D14: 150 | H14: VACIO
A15: 46151 | B15: RAMALLO | C15: LOMASER | D15: 300 | H15: 280116 | I15: ESCORIA
A16: 46152 | B16: LOMASER | C16: L. NEGRA | D16: 300 | H16: VACIO
A17: 46153 | B17: L. NEGRA | C17: B. DE ESCOBAR | D17: 430 | F17: 35.02 | H17: 771155
A18: 46154 | B18: B. ESCOBAR | C18: LOMASER | D18: 140 | H18: VACIO
A19: 46154 | B19: LOMASER | C19: URIBURU | D19: 340 | F19: 34.75 | H19: 900750
A20: 46155 | B20: URIBURU | C20: RAMALLO | D20: 80 | H20: VACIO
A21: 46155 | B21: RAMALLO | C21: LOMASER | D21: 300 | H21: 280329 | I21: ESCORIA
A22: 46156 | B22: LOMASER | C22: L. NEGRA | D22: 300 | H22: VACIO
A23: 46156 | B23: L. NEGRA | C23: B. DE ESCOBAR | D23: 430 | F23: 35.04 | H23: 771956
A24: 46157
A32: 46113 | B32: L. NEGRA | C32: PEHUAJO | D32: 230 | F32: 34.96 | H32: 764525 | K32: 1196752.1
A33: 46118 | B33: PEHUAJO | C33: SALAZAR | D33: 100 | H33: DERIVACION
A34: 46119 | B34: SALAZAR | C34: L. NEGRA | D34: 170 | H34: VACIO
A35: 46120 | B35: L. NEGRA | C35: OLAVARRIA | D35: 40 | F35: 35.28 | H35: 765177 | K35: 306705.97
A36: 46120 | B36: OLAVARRIA | C36: L. NEGRA | D36: 40 | H36: VACIO
A37: 46121 | B37: L. NEGRA | C37: COLON | D37: 440 | F37: 34.68 | H37: 765424
A38: 46122 | B38: COLON | C38: RAMALLO | D38: 140 | H38: VACIO
A39: 46122 | B39: RAMALLO | C39: LOMASER | D39: 300 | H39: 178847 | I39: ESCORIA
A40: 46123 | B40: LOMASER | C40: L. NEGRA | D40: 300 | H40: VACIO
A41: 46125 | B41: L. NEGRA | C41: OLAVARRIA | D41: 25 | F41: 34.98 | H41: 766071
A42: 46125 | B42: OLAVARRIA | C42: L. NEGRA | D42: 25 | H42: VACIO
A43: 46125 | B43: L. NEGRA | C43: NEUQUEN | D43: 830 | F43: 34.96 | H43: 766166 | K43: 3323016.9
A44: 46126 | B44: NEUQUEN | C44: L. NEGRA | D44: 830 | H44: VACIO
A45: 46127 | B45: L. NEGRA | C45: M. DEL PLATA | D45: 320 | F45: 35.24 | H45: 766440
A46: 46128 | B46: M. DEL PLATA | C46: L. NEGRA | D46: 320 | H46: VACIO
A47: 46128 | B47: L. NEGRA | C47: M. DEL PLATA | D47: 320 | F47: 34.7 | H47: 766670
...

Sheet SCHMIDT
A2: DIA | B2: SALE DE | C2: LLEGA A | D2: KM REC | E2: TN COM 29 | F2: TN ESC 35 | G2: TN ESC 37,5 | H2: REMITO Nº | I2: MATERIAL | J2: KM VACIOS | K2: $
A3: 46142 | B3: IBICUY | C3: AÑELO | D3: 1430 | H3: 125232 | I3: YPF
A4: 46145 | B4: AÑELO | C4: ALLEN | D4: 180 | H4: VACIO
A5: 46146 | B5: ALLEN | C5: L. NEGRA | D5: 820 | F5: 33.8 | H5: 189863 | I5: YESO LOMA
A6: 46147 | B6: L. NEGRA | C6: BERISSO | D6: 360 | F6: 34.94 | H6: 2950.. | I6: PIEDRA
A7: 46148 | B7: BERISSO | C7: IBICUY | D7: 280 | H7: VACIO
A8: 46148 | B8: IBICUY | C8: AÑELO | D8: 1430 | H8: 125350 | I8: YPF
A9: 46149 | B9: AÑELO | C9: L. NEGRA | D9: 940 | H9: VACIO
A10: 46151 | B10: L. NEGRA | C10: ZAPALA | D10: 1010 | H10: 621174 | I10: CLINKER
A11: 46153 | B11: ZAPALA | C11: ALLEN | D11: 240 | H11: VACIO
A12: 46154 | B12: ALLEN | C12: L. NEGRA | D12: 820 | F12: 33.7 | H12: 190274 | I12: YESO LOMA
A13: 46155 | B13: L. NEGRA | C13: CAMPANA | D13: 430 | F13: 35 | H13: 295892 | I13: PIEDRA
A14: 46156 | B14: CAMPANA | C14: IBICUY | D14: 100 | H14: VACIO
A15: 46156 | B15: IBICUY | C15: BANDUR | D15: 1470 | H15: 126926 | I15: YPF BANDUR
A16: 46158 | B16: BANDUR | C16: L. NEGRA | D16: 950 | H16: VACIO
A31: 46113 | B31: IBICUY | C31: AÑELO | D31: 1430 | H31: 80712 | I31: YPF
A32: 46116 | B32: AÑELO | C32: L. NEGRA | D32: 1040 | H32: VACIO
A33: 46119 | B33: L. NEGRA | C33: CAMPANA | D33: 420 | F33: 34.42 | H33: 619133 | I33: CLINKER
A34: 46119 | B34: CAMPANA | C34: SIDERAR | D34: 150 | H34: VACIO
A35: 46120 | B35: SIDERAR | C35: RAMALLO | D35: 10 | H35: 1063950 | I35: CORTO
A36: 46120 | B36: RAMALLO | C36: SIDERAR | D36: 10 | H36: VACIO
A37: 46120 | B37: SIDERAR | C37: RAMALLO | D37: 10 | H37: 1063968 | I37: CORTO
A38: 46120 | B38: RAMALLO | C38: SIDERAR | D38: 10 | H38: VACIO
A39: 46120 | B39: SIDERAR | C39: RAMALLO | D39: 10 | H39: 1063995 | I39: CORTO
A40: 46120 | B40: RAMALLO | C40: SIDERAR | D40: 10 | H40: VACIO
A41: 46120 | B41: SIDERAR | C41: RAMALLO | D41: 10 | H41: 1064015 | I41: CORTO
A42: 46120 | B42: RAMALLO | C42: SIDERAR | D42: 10 | H42: VACIO
A43: 46120 | B43: SIDERAR | C43: RAMALLO | D43: 10 | H43: 1064044 | I43: CORTO
A44: 46121 | B44: RAMALLO | C44: SIDERAR | D44: 10 | H44: VACIO
A45: 46121 | B45: SIDERAR | C45: RAMALLO | D45: 10 | H45: 1064147 | I45: CORTO
A46: 46121 | B46: RAMALLO | C46: L. NEGRA | D46: 500 | H46: ???? | I46: PALLETS
A47: 46122 | B47: L. NEGRA | C47: BARKER | D47: 180 | H47: 765624
A48: 46125 | B48: BARKER | C48: L. NEGRA | D48: 200 | H48: 182596 | I48: M. ROJO
A49: 46126 | B49: L. NEGRA | C49: ZAPALA | D49: 1010 | F49: 34.58 | H49: 619622 | I49: CLINKER
A50: 46127 | B50: ZAPALA | C50: ALLEN | D50: 240 | H50: VACIO
A51: 46128 | B51: ALLEN | C51: L. NEGRA | D51: 820 | F51: 33.8 | H51: 189592 | I51: YESO LOMA
A52: 46129 | B52: L. NEGRA | C52: ZAPALA | D52: 1010 | F52: 34.57 | H52: 619908 | I52: CLINKER
A53: 46133 | B53: ZAPALA | C53: ALLEN | D53: 240 | H53: VACIO
A54: 46134 | B54: ALLEN | C54: L. NEGRA | D54: 820 | F54: 34.1 | H54: 189810 | I54: YESO LOMA
A55: 46135 | B55: L. NEGRA | C55: CAMPANA | D55: 430 | F55: 34.52 | H55: 294444 | I55: PIEDRA
...

Sheet CEJAS
D1: JTN564
A2: DIA | B2: SALE DE | C2: LLEGA A | D2: KM REC | E2: TN COM 29 | F2: TN ESC 35 | G2: TN ESC 37,5 | H2: REMITO Nº | I2: MATERIAL | J2: KM VACIOS | K2: $
A3: 46142 | B3: ALLEN | C3: L. NEGRA | D3: 820 | F3: 33.5 | H3: 190073 | I3: YESO LOMA
A4: 46144 | B4: L. NEGRA | C4: ZAPALA | D4: 1010 | F4: 34.25 | H4: 620680 | I4: CLINKER
A5: 46147 | B5: ZAPALA | C5: ALLEN | D5: 240 | H5: VACIO
A6: 46147 | B6: ALLEN | C6: L. NEGRA | D6: 820 | F6: 33.5 | H6: 190095 | I6: YESO LOMA
A7: 46148 | B7: L. NEGRA | C7: PUNTA ALTA | D7: 370 | H7: 295169
A8: 46149 | B8: PUNTA ALTA | C8: L. NEGRA | D8: 370 | H8: VACIO
A9: 46151 | B9: L. NEGRA | C9: ZAPALA | D9: 1010 | H9: 621107 | I9: CLINKER
A10: 46153 | B10: ZAPALA | C10: V. REGINA | D10: 280 | H10: VACIO
A11: 46153 | B11: V. REGINA | C11: ALLEN | D11: 90 | H11: 163166
A12: 46154 | B12: ALLEN | C12: L. NEGRA | D12: 820 | F12: 34 | H12: 190432 | I12: YESO LOMA
A13: 46155 | B13: L. NEGRA | C13: TANDIL | D13: 150 | H13: 621453
A14: 46156 | B14: TANDIL | C14: L. NEGRA | D14: 150 | H14: VACIO
A15: 46156 | B15: L. NEGRA | C15: M. DEL PLATA | D15: 320 | H15: 771914
A16: 46157 | B16: M. DEL PLATA | C16: L. NEGRA | D16: 320 | H16: PALLETS | I16: 1 CLIENTE
A29: 46113 | B29: ADELA 6 | C29: L. NEGRA | D29: 970 | H29: VACIO
A30: 46116 | B30: L. NEGRA | C30: CAMPANA | D30: 420 | F30: 34.94 | H30: 619007 | I30: CLINKER
A31: 46118 | B31: CAMPANA | C31: SIDERAR | D31: 150 | H31: VACIO
A32: 46118 | B32: SIDERAR | C32: RAMALLO | D32: 10 | H32: 1063483 | I32: CORTO
A33: 46119 | B33: RAMALLO | C33: SIDERAR | D33: 10 | H33: VACIO
A34: 46119 | B34: SIDERAR | C34: RAMALLO | D34: 10 | H34: 1063606 | I34: CORTO
A35: 46119 | B35: RAMALLO | C35: L. NEGRA | D35: 500 | F35: 34.01 | H35: 1063679 | I35: LODO
A36: 46120 | B36: L. NEGRA | C36: CAMPANA | D36: 420 | F36: 34.68 | H36: 619233 | I36: CLINKER
A37: 46121 | B37: CAMPANA | C37: SIDERAR | D37: 150 | H37: VACIO
A38: 46121 | B38: SIDERAR | C38: RAMALLO | D38: 10 | H38: 1064286 | I38: CORTO
A39: 46122 | B39: RAMALLO | C39: SIDERAR | D39: 10 | H39: VACIO
A40: 46122 | B40: SIDERAR | C40: RAMALLO | D40: 10 | H40: 1064365 | I40: CORTO
A41: 46122 | B41: RAMALLO | C41: L. NEGRA | D41: 500 | H41: 1064490 | I41: LODO
A42: 46126 | B42: L. NEGRA | C42: CAMPANA | D42: 420 | F42: 34.66 | H42: 619581 | I42: CLINKER
A43: 46127 | B43: CAMPANA | C43: SIDERCA | D43: 10 | H43: VACIO
A44: 46127 | B44: CAMPANA | C44: CATAMARCA | D44: 990 | F44: 33.8 | H44: 153208 | I44: SIDERCA
A45: 46128 | B45: CATAMARCA | C45: FERREYRA | D45: 390 | H45: 504061
A46: 46129 | B46: FERREYRA | C46: PAMPAYASTA | D46: 120 | H46: VACIO
A47: 46129 | B47: PAMPAYASTA | C47: ROSARIO | D47: 340 | F47: 33.1 | H47: TKT 21650
A48: 46130 | B48: ROSARIO | C48: RAMALLO | D48: 80 | H48: VACIO
A49: 46130 | B49: RAMALLO | C49: L. NEGRA | D49: 500 | F49: 34.24 | H49: 1065841 | I49: LODO
A50: 46135 | B50: L. NEGRA | C50: CAMPANA | D50: 430 | H50: 292,,, | I50: PIEDRA
A51: 46136 | B51: CAMPANA | C51: RAMALLO | D51: 150 | H51: VACIO
A52: 46136 | B52: RAMALLO | C52: ZAPALA | D52: 1470 | F52: 33.92 | H52: 1066905 | I52: LODO
...

Sheet VALERGA
A2: DIA | B2: SALE DE | C2: LLEGA A | D2: KM REC | E2: TN COM 29 | F2: TN ESC 35 | G2: TN ESC 37,5 | H2: REMITO Nº | I2: MATERIAL | J2: KM VACIOS | K2: $
A3: 46143 | B3: IBICUY | C3: BAJO DEL TORO | D3: 1560 | H3: 124223 | I3: YPF TORO
A4: 46146 | B4: BAJO DEL TORO | C4: ALLEN | D4: 270 | H4: VACIO
A5: 46147 | B5: ALLEN | C5: L. NEGRA | D5: 820 | F5: 35.5 | H5: 189873 | I5: YESO LOMA
A6: 46148 | B6: L. NEGRA | C6: M. DEL PLATA | D6: 320 | H6: 769862
A7: 46149 | B7: M. DEL PLATA | C7: L. NEGRA | D7: 320 | H7: VACIO
A8: 46150 | B8: L. NEGRA | C8: CAMPANA | D8: 420 | F8: 36.66 | H8: 621039 | I8: CLINKER
A9: 46151 | B9: CAMPANA | C9: IBICUY | D9: 85 | H9: VACIO
A10: 46151 | B10: IBICUY | C10: BANDUR | D10: 1470 | H10: 125942 | I10: YPF BANDUR
A11: 46154 | B11: BANDUR | C11: L. NEGRA | D11: 950 | H11: VACIO
A28: 46113 | B28: ADELA 6 | C28: L. NEGRA | D28: 1070 | H28: VACIO
A29: 46116 | B29: L. NEGRA | C29: CAMPANA | D29: 420 | G29: 36.91 | H29: 618977 | I29: CLINKER
A30: 46118 | B30: CAMPANA | C30: IBICUY | D30: 85 | H30: VACIO
A31: 46119 | B31: IBICUY | C31: BAJO DEL TORO | D31: 1560 | H31: 119681 | I31: YPF TORO
A32: 46122 | B32: BAJO DEL TORO | C32: L. NEGRA | D32: 1070 | H32: VACIO
A33: 46123 | B33: L. NEGRA | C33: ZAPALA | D33: 1010 | G33: 36.36 | H33: 619511 | I33: CLINKER
A34: 46126 | B34: ZAPALA | C34: ALLEN | D34: 240 | H34: VACIO
A35: 46126 | B35: ALLEN | C35: L. NEGRA | D35: 820 | G35: 34.7 | H35: 189472 | I35: YESO LOMA | K35: 949499.51
A36: 46128 | B36: L. NEGRA | C36: ZAPALA | D36: 1010 | G36: 36.51 | H36: 619789 | I36: CLINKER
A37: 46129 | B37: ZAPALA | C37: L. NEGRA | D37: 1060 | H37: 16418 | I37: TANDILIA
A38: 46135 | B38: L. NEGRA | C38: CAMPANA | D38: 430 | H38: 292… | I38: PIEDRA
A39: 46136 | B39: CAMPANA | C39: IBICUY | D39: 85 | H39: VACIO
A40: 46136 | B40: IBICUY | C40: BAJO DEL TORO | D40: 1560 | H40: 122785 | I40: YPF TORO
A41: 46139 | B41: BAJO DEL TORO | C41: ALLEN | D41: 270 | H41: VACIO
A42: 46140 | B42: ALLEN | C42: L. NEGRA | D42: 820 | G42: 36.1 | H42: 189990 | I42: YESO LOMA
A43: 46142 | B43: L. NEGRA | C43: C. FEDERAL | D43: 390 | G43: 35.84 | H43: 294831 | I43: PIEDRA
A44: 46142 | B44: C. FEDERAL | C44: IBICUY | D44: 170 | H44: VACIO
D45: 30 A LAS 22
D47: =SUM(D3:D46) -> 18285 | F47: =AVERAGE(#REF!) -> #REF! | G47: =AVERAGE(G3:G45) -> 36.07 | J47: =SUM(J3:J46) -> 0 | K47: =SUM(K3:K46) -> 949499.51 | L47: =K47/D47 -> 51.927783
B49: -1968.2
B50: 630 | C50: PEAJES | K50: 267km
B51: -700 | C51: ADELANTO
B52: 630 | C52: PEAJES
B53: -600 | C53: ADELANTO
B54: 1110 | C54: PEAJES
B55: -1200 | C55: ADELANTO
B56: 680 | C56: PEAJES | D56: 44131
B57: -600 | C57: ADELANTO
B58: 400 | C58: PEAJES
B59: -400 | C59: ADELANTO
...

Sheet PUCHETA
D1: LSN 102
A2: DIA | B2: SALE DE | C2: LLEGA A | D2: KM REC | E2: TN COM 29 | F2: TN ESC 35 | G2: TN ESC 37,5 | H2: REMITO Nº | I2: MATERIAL | J2: KM VACIOS | K2: $
A3: 46142 | B3: L. NEGRA | C3: CAMPANA | D3: 420 | F3: 34.46 | H3: 620612 | I3: CLINKER
A4: 46144 | B4: CAMPANA | C4: IBICUY | D4: 85 | H4: VACIO
A5: 46144 | B5: IBICUY | C5: BAJO DEL TORO | D5: 1560 | H5: 124501 | I5: YPF TORO
A6: 46148 | B6: BAJO DEL TORO | C6: ALLEN | D6: 270 | H6: VACIO
A7: 46150 | B7: ALLEN | C7: L. NEGRA | D7: 820 | F7: 34.7 | H7: 190217 | I7: YESO LOMA
A8: 46153 | B8: L. NEGRA | C8: ZAPALA | D8: 1010 | H8: 621266 | I8: CLINKER
A9: 46154 | B9: ZAPALA | C9: ALLEN | D9: 240 | H9: VACIO
A10: 46155 | B10: ALLEN | C10: L. NEGRA | D10: 820 | F10: 34.8 | H10: 190447 | I10: YESO LOMA
A11: 46157 | B11: L. NEGRA | C11: CAMPANA | D11: 420 | F11: 34.79 | H11: 621578 | I11: CLINKER
A12: 46157 | B12: CAMPANA | C12: IBICUY | D12: 85 | H12: VACIO
A26: 46112 | B26: IBICUY | C26: ADELA 6 | D26: 1450 | H26: 118504 | I26: ADELA YPF
A27: 46114 | B27: ADELA 6 | C27: L. NEGRA | D27: 1070 | H27: VACIO
A28: 46119 | B28: L. NEGRA | C28: CAMPANA | D28: 420 | F28: 35.12 | H28: 619142 | I28: CLINKER
A29: 46120 | B29: CAMPANA | C29: IBICUY | D29: 85 | H29: VACIO
A30: 46120 | B30: IBICUY | C30: BAJO DEL TORO | D30: 1560 | H30: 119914 | I30: YPF TORO
A31: 46123 | B31: BAJO DEL TORO | C31: L. NEGRA | D31: 1070 | H31: VACIO
A32: 46126 | B32: L. NEGRA | C32: RIO CUARTO | D32: 730 | H32: 766240
A33: 46127 | B33: RIO CUARTO | C33: PAMPAYASTA | D33: 140 | H33: VACIO
A34: 46127 | B34: PAMPAYASTA | C34: ROSARIO | D34: 340 | F34: 36.1 | H34: TKT 21557
A35: 46128 | B35: ROSARIO | C35: RAMALLO | D35: 80 | H35: VACIO
A36: 46128 | B36: RAMALLO | C36: L. NEGRA | D36: 500 | F36: 35.59 | H36: 1065369 | I36: LODO
A37: 46129 | B37: L. NEGRA | C37: ZAPALA | D37: 1010 | F37: 35.21 | H37: 619896 | I37: CLINKER
A38: 46132 | B38: ZAPALA | C38: ALLEN | D38: 240 | H38: VACIO
A39: 46133 | B39: ALLEN | C39: L. NEGRA | D39: 820 | F39: 34 | H39: 189785 | I39: YESO LOMA
A40: 46135 | B40: L. NEGRA | C40: ZAPALA | D40: 1010 | F40: 34.5 | H40: 620187 | I40: CLINKER
A41: 46136 | B41: ZAPALA | C41: ALLEN | D41: 240 | H41: VACIO
A42: 46136 | B42: ALLEN | C42: L. NEGRA | D42: 820 | F42: 34.2 | H42: 189919 | I42: YESO LOMA
A43: 46139 | B43: L. NEGRA | C43: TORCUATO | D43: 400 | F43: 34.74 | H43: 294655 | I43: PIEDRA
A44: 46140 | B44: TORCUATO | C44: LOMASER | D44: 140 | H44: VACIO
A45: 46140 | B45: LOMASER | C45: RAMALLO | D45: 300 | H45: 5302 | I45: PALLET
A46: 46141 | B46: RAMALLO | C46: L. NEGRA | D46: 500 | F46: 35.55 | H46: 1067730 | I46: ESCORIA
D47: 30 A LAS 11
D49: =SUM(D3:D48) -> 18655 | F49: =AVERAGE(F3:F47) -> 34.904615 | J49: =SUM(J3:J48) -> 0 | K49: =SUM(K3:K48) -> 0
B51: -2222.5
B52: 200 | C52: PEAJES
B53: 2800 | C53: PEAJES
B54: -2800 | C54: ADELANTO | D54: 44055
B55: 200 | C55: PEAJES
...

Sheet CALIGIURI
D1: AE 601 GF
A2: DIA | B2: SALE DE | C2: LLEGA A | D2: KM REC | E2: TN COM 29 | F2: TN ESC 35 | G2: TN ESC 37,5 | H2: REMITO Nº | I2: MATERIAL | J2: KM VACIOS | K2: $
A30: 46112 | B30: ALLEN | C30: L. NEGRA | D30: 820 | G30: 35.8 | H30: 189341 | I30: YESO LOMA
A31: 46118 | B31: L. NEGRA | C31: CAMPANA | D31: 420 | G31: 36.19 | H31: 619080 | I31: CLINKER
A32: 46119 | B32: CAMPANA | C32: SIDERAR | D32: 150 | H32: VACIO
A33: 46119 | B33: SIDERAR | C33: RAMALLO | D33: 10 | H33: 1063787 | I33: CORTO
A34: 46119 | B34: RAMALLO | C34: SIDERAR | D34: 10 | H34: VACIO
A35: 46119 | B35: SIDERAR | C35: RAMALLO | D35: 10 | H35: 1063710 | I35: CORTO
A36: 46119 | B36: RAMALLO | C36: L. NEGRA | D36: 500 | H36: 1063826 | I36: ESCORIA
A37: 46120 | B37: L. NEGRA | C37: M. DEL PLATA | D37: 320 | H37: 765296 | K37: 907612.2
A38: 46121 | B38: M. DEL PLATA | C38: BARKER | D38: 230 | H38: VACIO
A39: 46122 | B39: BARKER | C39: L. NEGRA | D39: 200 | H39: 182570 | I39: M. ROJO
A40: 46139 | B40: L. NEGRA | C40: CAMPANA | D40: 430 | G40: 35.34 | H40: 294654 | I40: PIEDRA
A41: 46140 | B41: CAMPANA | C41: SIDERCA | D41: 10 | H41: VACIO
A42: 46140 | B42: SIDERCA | C42: CATAMARCA | D42: 990 | G42: 35.9 | H42: 153462 | I42: SIDERCA
A43: 46141 | B43: CATAMARCA | C43: CORDOBA | D43: 380 | H43: 504954
A44: 46141 | B44: CORDOBA | C44: SAN AGUSTIN | D44: 150 | H44: VACIO
A45: 46141 | B45: SAN AGUSTIN | C45: ROSARIO | D45: 450 | H45: PIEDRA | I45: LA ELENA
A46: 46142 | B46: ROSARIO | C46: IBICUY | D46: 300 | H46: VACIO
D47: 30 A LAS 20
J48: =SUM(J3:J47) -> 0
D49: =SUM(D3:D48) -> 5380 | G49: =AVERAGE(G3:G47) -> 35.8075 | K49: =SUM(K3:K48) -> 907612.2
B51: -2064.02
B52: 600 | C52: PEAJES
B53: -600 | C53: ADELANTO
B54: 795 | C54: PEAJES
B55: -800 | C55: ADELANTO
B56: 400 | C56: PEAJES
B57: -400 | C57: ADELANTO
B58: 795 | C58: PEAJES
B59: -800 | C59: ADELANTO
B60: 200 | C60: PEAJES
B61: -200 | C61: ADELANTO
B62: 760 | C62: PEAJES | D62: 44123
B63: -700 | C63: ADELANTO | D63: 44123
B64: 310 | C64: peajes | D64: 44125
B65: -300 | C65: ADELANTO | D65: 44125
B66: 200 | C66: PEAJES
B67: -200 | C67: ADELANTO
B68: 200 | C68: PEAJES | D68: 44139
...

Sheet ASTEAZARAN
C1: AA244ZI
A2: DIA | B2: SALE DE | C2: LLEGA A | D2: KM REC | E2: TN COM 29 | F2: TN ESC 35 | G2: TN ESC 37,5 | H2: REMITO Nº | I2: MATERIAL | J2: KM VACIOS | K2: $
A3: 46142 | B3: L. NEGRA | C3: CAMPANA | D3: 430 | F3: 34.46 | H3: 620612 | I3: PIEDRA
A4: 46114 | B4: CAMPANA | C4: IBICUY | D4: 100 | H4: VACIO
A25: 46112 | B25: IBICUY | C25: ADELA 6 | D25: 1490 | H25: 118338 | I25: ADELA YPF
A26: 46114 | B26: ADELA 6 | C26: L. NEGRA | D26: 970 | H26: VACIO
A27: 46118 | B27: L. NEGRA | C27: CAMPANA | D27: 420 | F27: 34.84 | H27: 619082 | I27: CLINKER
A28: 46119 | B28: CAMPANA | C28: SIDERAR | D28: 150 | H28: VACIO
A29: 46119 | B29: SIDERAR | C29: RAMALLO | D29: 10 | H29: 1063714 | I29: CORTO
A30: 46119 | B30: RAMALLO | C30: SIDERAR | D30: 10 | H30: VACIO
A31: 46119 | B31: SIDERAR | C31: RAMALLO | D31: 10 | H31: 1063788 | I31: CORTO
A32: 46119 | B32: RAMALLO | C32: L. NEGRA | D32: 500 | F32: 33.91 | H32: 1063821 | I32: ESCORIA
A33: 46121 | B33: L. NEGRA | C33: VICTORIA | D33: 430 | H33: 293566 | I33: PIEDRA
A34: 46122 | B34: VICTORIA | C34: IBICUY | D34: 150 | H34: VACIO
A35: 46122 | B35: IBICUY | C35: BAJO DEL TORO | D35: 1560 | H35: 120342 | I35: YPF TORO
A36: 46125 | B36: BAJO DEL TORO | C36: ALLEN | D36: 270 | H36: VACIO
A37: 46126 | B37: ALLEN | C37: L. NEGRA | D37: 820 | F37: 35 | H37: 189439 | I37: YESO LOMA
A38: 46127 | B38: L. NEGRA | C38: CAMPANA | D38: 420 | F38: 34.59 | H38: 619722 | I38: CLINKER
A39: 46128 | B39: CAMPANA | C39: RAMALLO | D39: 150 | H39: VACIO
A40: 46128 | B40: RAMALLO | C40: L. NEGRA | D40: 500 | F40: 35.27 | H40: 1065460 | I40: ESCORIA
A41: 46129 | B41: L. NEGRA | C41: ZAPALA | D41: 1010 | F41: 34.53 | H41: 619899 | I41: CLINKER
A42: 46132 | B42: ZAPALA | C42: ALLEN | D42: 240 | H42: VACIO
A43: 46132 | B43: ALLEN | C43: ZAPALA | D43: 240 | F43: 33.8 | H43: 189748 | I43: CORTO YESO
A44: 46133 | B44: ZAPALA | C44: ALLEN | D44: 240 | H44: VACIO
A45: 46133 | B45: ALLEN | C45: L. NEGRA | D45: 820 | F45: 33.8 | H45: 189790 | I45: YESO LOMA
A46: 46135 | B46: L. NEGRA | C46: CAMPANA | D46: 430 | H46: 294373 | I46: PIEDRA
A47: 46136 | B47: CAMPANA | C47: IBICUY | D47: 100 | H47: VACIO
A48: 46136 | B48: IBICUY | C48: AÑELO | D48: 1430 | H48: 112803 | I48: YPF
A49: 46140 | B49: AÑELO | C49: ALLEN | D49: 180 | H49: VACIO
A50: 46140 | B50: ALLEN | C50: L. NEGRA | D50: 820 | F50: 34.3 | H50: 189998 | I50: YESO LOMA
A51: 46141 | B51: L. NEGRA | C51: TORCUATO | D51: 400 | H51: ????
A52: 46142 | B52: TORCUATO | C52: IBICUY | D52: 150 | H52: VACIO
D53: 30 A LAS 16
J54: =SUM(J3:J53) -> 0
D55: =SUM(D3:D54) -> 14450 | F55: =AVERAGE(F3:F53) -> 34.45 | K55: =SUM(K3:K53) -> 0
B57: -2015
B58: 1390 | C58: PEAJES | D58: 44069
B59: 600 | C59: LAVADO
B60: -2000 | C60: ADELANTO
B61: 630 | C61: PEAJES | D61: 44103
...

Sheet GARMENDIA
F1: PFN894
A2: DIA | B2: SALE DE | C2: LLEGA A | D2: KM REC | E2: TN COM 29 | F2: TN ESC 35 | G2: TN ESC 37,5 | H2: REMITO Nº | I2: MATERIAL | J2: KM VACIOS | K2: $
A26: 46111 | B26: L. NEGRA | C26: VICTORIA | D26: 430 | H26: 292957 | I26: PIEDRA
A27: 46113 | B27: VICTORIA | C27: IBICUY | D27: 150 | H27: VACIO
A28: 46114 | B28: IBICUY | C28: AÑELO | D28: 1430 | H28: 118786 | I28: YPF
A29: 46115 | B29: AÑELO | C29: L. NEGRA | D29: 1040 | H29: VACIO
A30: 46120 | B30: L. NEGRA | C30: BAHIA BLANCA | D30: 320
A31: 46121 | B31: BAHIA BLANCA | C31: L. NEGRA | D31: 320
A32: 46122 | B32: L. NEGRA | C32: S. FERNANDO | D32: 420 | F32: 35.02 | H32: 293676 | I32: FENOMIX
A33: 46125 | B33: S. FERNANDO | C33: IBICUY | D33: 150 | H33: VACIO
A34: 46125 | B34: IBICUY | C34: BAJO DEL TORO | D34: 1560 | H34: 120901 | I34: YPF TORO
A35: 46127 | B35: BAJO DEL TORO | C35: ALLEN | D35: 270 | H35: VACIO
A36: 46128 | B36: ALLEN | C36: L. NEGRA | D36: 820 | F36: 34.2 | H36: 189557 | I36: YESO LOMA
A37: 46129 | B37: L. NEGRA | C37: CASEROS | D37: 380 | H37: ???? | I37: TRAMONTANA
A38: 46132 | B38: CASEROS | C38: IBICUY | D38: 180 | H38: VACIO
A39: 46132 | B39: IBICUY | C39: BAJO DEL TORO | D39: 1560 | H39: 121979 | I39: YPF TORO
A40: 46135 | B40: BAJO DEL TORO | C40: ALLEN | D40: 270 | H40: VACIO
A41: 46136 | B41: ALLEN | C41: L. NEGRA | D41: 820 | F41: 34.1 | H41: 189878 | I41: YESO LOMA
A42: 46137 | B42: L. NEGRA | C42: SAN EFRNANDO | D42: 420 | H42: 294580
A43: 46139 | B43: SAN FERNANDO | C43: IBICUY | D43: 150 | H43: VACIO
A44: 46139 | B44: IBICUY | C44: AÑELO | D44: 1430 | H44: ???? | I44: YPF
D45: 30 A LAS 23
D47: =SUM(D3:D46) -> 12120 | F47: =AVERAGE(F3:F45) -> 34.44 | J47: =SUM(J3:J46) -> 0 | K47: =SUM(K3:K46) -> 0
B49: -2017
B50: 455 | C50: PEAJES
B51: -500 | C51: ADELANTO
B52: 140 | C52: PEAJES
B53: -200 | C53: ADELANTO
B54: 515 | C54: PEAJES
B55: -500 | C55: ADELANTO
B56: 280 | C56: PEAJES
B57: -200 | C57: ADELANTO
B58: 220 | C58: PEAJES | D58: 44149
B59: 200 | C59: PEAJES | D59: 44167
B60: -400 | C60: ADELANTO
B61: 220 | C61: PEAJES | D61: 44186
B62: -200 | C62: ADELANTO | D62: 44186
B63: 200 | C63: PEAJES | D63: 44188
B64: -200 | C64: ADELANTO | D64: 44188
B65: 465 | C65: PEAJES
...

Sheet SALTO
D1: AD242JZ
A2: DIA | B2: SALE DE | C2: LLEGA A | D2: KM REC | E2: TN COM 29 | F2: TN ESC 35 | G2: TN ESC 37,5 | H2: REMITO Nº | I2: MATERIAL | J2: KM VACIOS | K2: $
A26: 46111 | B26: DOCK SUD | C26: T. SUAREZ | D26: 70 | G26: TALLER | H26: VOLVO
A27: 46084 | B27: T. SUAREZ | C27: IBICUY | D27: 220 | H27: VACIO
A28: 46115 | B28: IBICUY | C28: BAJO DEL TORO | D28: 1560 | H28: 80746 | I28: YPF TORO
A29: 46119 | B29: BAJO DEL TORO | C29: L. NEGRA | D29: 1070 | H29: VACIO
A30: 46122 | B30: L. NEGRA | C30: SPEGAZZINI | D30: 350 | G30: 35.14 | H30: 293670 | I30: PIEDRA
A31: 46094 | B31: SPEGAZZINI | C31: LOMASER | D31: 20 | H31: VACIO
A32: 46125 | B32: LOMASER | C32: J. C. PAZ | D32: 120 | H32: 895883
A33: 46125 | B33: J. C. PAZ | C33: CAÑUELAS | D33: 120 | H33: VACIO
A34: 46125 | B34: CAÑUELAS | C34: RAMALLO | D34: 300 | H34: 5258 | I34: PALLETS | K34: 329603.71
A35: 46125 | B35: RAMALLO | C35: L. NEGRA | D35: 500 | H35: 1064909 | I35: LODO
A36: 46127 | B36: L. NEGRA | C36: ZAPALA | D36: 1010 | G36: 36.25 | H36: 619692 | I36: CLINKER
A37: 46128 | B37: ZAPALA | C37: ALLEN | D37: 240 | H37: VACIO
A38: 46128 | B38: ALLEN | C38: L. NEGRA | D38: 850 | G38: 33 | H38: 189632 | I38: YESO LOMA
A39: 46130 | B39: L. NEGRA | C39: ZAPALA | D39: 1010 | H39: 619973 | I39: CLINKER
A40: 46132 | B40: ZAPALA | C40: ALLEN | D40: 240 | H40: VACIO
A41: 46132 | B41: ALLEN | C41: L. NEGRA | D41: 850 | G41: 36 | H41: 189730 | I41: YESO LOMA
A42: 46134 | B42: L. NEGRA | C42: ZAPALA | D42: 1010 | G42: 36.64 | H42: 620156 | I42: CLINKER
A43: 46135 | B43: ZAPALA | C43: ALLEN | D43: 240 | H43: VACIO
A44: 46136 | B44: ALLEN | C44: L. NEGRA | D44: 850 | G44: 35.5 | H44: 189849 | I44: YESO LOMA
D45: 25 A LAS 8 | E45: LF
D47: =SUM(D3:D46) -> 10630 | G47: =AVERAGE(G3:G45) -> 35.421667 | J47: =SUM(J3:J46) -> 0 | K47: =SUM(K3:K46) -> 329603.71 | L47: =K47/D47 -> 31.006934
B49: -2106 | C49: ADELANTO
B50: 630 | C50: PEAJES
B51: -600 | C51: ADELANTO
B52: 630 | C52: PEAJES
B53: -600 | C53: ADELANTO | D53: 44111
B54: 1065 | C54: PEAJES Y GOMERIA
B55: -1100 | C55: ADELANTO | D55: 44118
B56: 600 | C56: EMPARCHE GOMERIA | D56: 44123
B57: 140 | C57: PEAJES
B58: -700 | C58: ADELANTO
B59: 800 | C59: ARREGLO DE LONA | D59: 44130
B60: -800 | C60: ADELANTO
B61: 220 | C61: PEAJES | D61: 44140
B62: 220 | C62: PEAJES | D62: 44148
B63: 800 | C63: gomeria | D63: 44161
B64: -1200 | C64: ADELANTO | D64: 44161
B65: 340 | C65: PEAJES
...

Sheet BAZAN
D1: JKQ716
A2: DIA | B2: SALE DE | C2: LLEGA A | D2: KM REC | E2: TN COM 29 | F2: TN ESC 35 | G2: TN ESC 37,5 | H2: REMITO Nº | I2: MATERIAL | J2: KM VACIOS | K2: $
A23: 46113 | B23: L. NEGRA | C23: CASEROS | D23: 380 | F23: 34.44 | H23: 293227 | I23: TRAMONTANA | K23: 619920
A24: 46118 | B24: CASEROS | C24: IBICUY | D24: 180 | H24: VACIO
A25: 46118 | B25: IBICUY | C25: AÑELO | D25: 1430 | H25: 119477 | I25: YPF
A26: 46121 | B26: AÑELO | C26: L. NEGRA | D26: 1000 | H26: VACIO
A27: 46123 | B27: L. NEGRA | C27: ZAPALA | D27: 1010 | F27: 33.91 | H27: 619460 | I27: CLINKER | K27: 2227070.5
A28: 46125 | B28: ZAPALA | C28: ALLEN | D28: 240 | H28: VACIO
A29: 46125 | B29: ALLEN | C29: L. NEGRA | D29: 820 | F29: 34.7 | H29: 189454 | I29: YESO LOMA | K29: 972132.93
A30: 46126 | B30: L. NEGRA | C30: CAMPANA | D30: 420 | F30: 34.25 | H30: 619657 | I30: CLINKER
A31: 46127 | B31: CAMPANA | C31: SIDERAR | D31: 150 | H31: VACIO
A32: 46127 | B32: SIDERAR | C32: L. NEGRA | D32: 500 | F32: 34.03 | H32: 1065172 | I32: ESCORIA
A33: 46129 | B33: L. NEGRA | C33: ZAPALA | D33: 1010 | F33: 34.26 | H33: 619847 | I33: CLINKER
A34: 46132 | B34: ZAPALA | C34: ALLEN | D34: 240 | H34: VACIO
A35: 46132 | B35: ALLEN | C35: ZAPALA | D35: 240 | F35: 33.6 | H35: 189745 | I35: YESO LOMA
A36: 46133 | B36: ZAPALA | C36: ALLEN | D36: 240 | H36: VACIO
A37: 46133 | B37: ALLEN | C37: L. NEGRA | D37: 820 | F37: 33.8 | H37: 189791 | I37: YESO LOMA
A38: 46135 | B38: L. NEGRA | C38: CAMPANA | D38: 430 | H38: ???? | I38: PIEDRA
A39: 46136 | B39: CAMPANA | C39: IBICUY | D39: 100 | H39: VACIO
A40: 46136 | B40: IBICUY | C40: BAJO DEL TORO | D40: 1470 | H40: 122776 | I40: YPF TORO 5
A41: 46141 | B41: BAJO DEL TORO | C41: L. NEGRA | D41: 1070 | H41: VACIO
D42: 30 A LAS 13
D44: =SUM(D3:D43) -> 11750 | F44: =AVERAGE(F3:F42) -> 34.12375 | J44: =SUM(J3:J43) -> 0 | K44: =SUM(K3:K43) -> 3819123.4
B46: -2130
B47: 200 | C47: PEAJES
B48: -200 | C48: ADELANTO
B49: 200 | C49: PEAJES
B50: -200 | C50: ADELANTO
B51: 215 | C51: PEAJES | D51: 44105 | I51: 10000
B52: -200 | C52: ADELANTO | I52: 7000
B53: 130 | C53: PEAJES | I53: 10000
B54: 200 | C54: PEAJES | I54: 10000
B55: -300 | C55: ADELANTO | I55: 10000
B56: 480 | C56: PEAJES | I56: 7000
B57: -400 | C57: ADELANTO | D57: 44123 | I57: 10000
B58: 1000 | C58: PARCHE GOMA | D58: 44127 | I58: 10000
B59: -1000 | C59: ADELANTO | I59: 7000
B60: 630 | C60: PEAJES | D60: 44127 | I60: 10000
B61: -700 | C61: ADELANTO | I61: 10000
B62: 400 | C62: PEAJES | D62: 44140 | I62: 10000
...

Sheet BORDIGNON
D1: AB742XZ
A2: DIA | B2: SALE DE | C2: LLEGA A | D2: KM REC | E2: TN COM 29 | F2: TN ESC 35 | G2: TN ESC 37,5 | H2: REMITO Nº | I2: MATERIAL | J2: KM VACIOS | K2: $
A29: 46112 | B29: L. NEGRA | C29: RAMALLO | D29: 500 | H29: 618865
A30: 46113 | B30: RAMALLO | C30: SIDERAR | D30: 10 | H30: VACIO
A31: 46113 | B31: SIDERAR | C31: RAMALLO | D31: 10 | H31: 1062968 | I31: CORTO
A32: 46113 | B32: RAMALLO | C32: L. NEGRA | D32: 500 | F32: 34.45 | H32: 1063032 | I32: ESCORIA
A33: 46118 | B33: L. NEGRA | C33: M. DEL PLATA | D33: 320 | H33: 764963 | K33: 857189.3
A34: 46119 | B34: M. DEL PLATA | C34: L. NEGRA | D34: 320 | H34: VACIO
A35: 46120 | B35: L. NEGRA | C35: BARKER | D35: 180 | H35: 765168
A36: 46120 | B36: BARKER | C36: L. NEGRA | D36: 220 | H36: 33294 | I36: ARCAMIN
A37: 46120 | B37: L. NEGRA | C37: JUNIN | D37: 325 | H37: 619282 | K37: 1017282.2
A38: 46121 | B38: JUNIN | C38: L. NEGRA | D38: 325 | H38: VACIO
A39: 46121 | B39: L. NEGRA | C39: BARKER | D39: 180 | H39: 765468
A40: 46122 | B40: BARKER | C40: L. NEGRA | D40: 200 | H40: 182565 | I40: M. ROJO
A41: 46123 | B41: L. NEGRA | C41: ZAPALA | D41: 1010 | F41: 35.21 | H41: 619507 | I41: CLINKER | K41: 2312449.1
A42: 46125 | B42: ZAPALA | C42: ALLEN | D42: 240 | H42: VACIO
A43: 46125 | B43: ALLEN | C43: L. NEGRA | D43: 820 | F43: 35 | H43: 189456 | I43: YESO LOMA | K43: 970476.83
A44: 46126 | B44: L. NEGRA | C44: CAMPANA | D44: 430 | H44: 293868 | I44: PIEDRA
A45: 46127 | B45: CAMPANA | C45: SIDERCA | D45: 10 | H45: VACIO
A46: 46127 | B46: SIDERCA | C46: CATAMARCA | D46: 990 | F46: 34.44 | H46: 153207 | I46: SIDERCA
A47: 46128 | B47: CATAMARCA | C47: ALTA GRACIA | D47: 430 | H47: 504060
A48: 46129 | B48: ALTA GRACIA | C48: PAMPAYASTA | D48: 150 | H48: VACIO
A49: 46130 | B49: PAMPAYASTA | C49: ROSARIO | D49: 370 | F49: 35.7 | H49: TKT 21648
A50: 46130 | B50: ROSARIO | C50: RAMALLO | D50: 80 | H50: VACIO
A51: 46130 | B51: RAMALLO | C51: L. NEGRA | D51: 500 | F51: 34.67 | H51: 1065812 | I51: LODO
A52: 46134 | B52: L. NEGRA | C52: CAMPANA | D52: 430 | F52: 34.68 | H52: 294340 | I52: PIEDRA
A53: 46135 | B53: CAMPANA | C53: IBICUY | D53: 100 | H53: VACIO
A54: 46136 | B54: IBICUY | C54: BAJO DEL TORO | D54: 1560 | H54: 122669 | I54: YPF TORO
A55: 46138 | B55: BAJO DEL TORO | C55: ALLEN | D55: 270 | H55: VACIO
A56: 46139 | B56: ALLEN | C56: L. NEGRA | D56: 820 | F56: 34.2 | H56: 189965 | I56: YESO LOMA
A57: 46140 | B57: L. NEGRA | C57: CHACABUCO | D57: 360 | H57: 620478
A58: 46141 | B58: CHACABUCO | C58: RAMALLO | D58: 180 | H58: VACIO
A59: 46141 | B59: RAMALLO | C59: L. NEGRA | D59: 500 | F59: 34.86 | H59: 1067745 | I59: ESCORIA
D60: 30 A LAS 11
D62: =SUM(D3:D61) -> 12340 | F62: =AVERAGE(F3:F60) -> 34.801111 | J62: =SUM(J3:J61) -> 0 | K62: =SUM(K3:K61) -> 5157397.4
B64: -2020
B65: 520 | C65: PEAJES | D65: 44098
B66: -500 | C66: ADELANTO | D66: 44098
B67: 480 | C67: PEAJES
B68: -500 | C68: ADELANTO
...

Sheet LAGANO D
D1: NYU 938
A2: DIA | B2: SALE DE | C2: LLEGA A | D2: KM REC | E2: TN COM 29 | F2: TN ESC 35 | G2: TN ESC 37,5 | H2: REMITO Nº | I2: MATERIAL | J2: KM VACIOS | K2: $
A29: 46112 | B29: SIDERAR | C29: L. NEGRA | D29: 500 | F29: 34.93 | H29: 1062780 | I29: ESCORIA
A30: 46118 | B30: L. NEGRA | C30: CAMPANA | D30: 420 | F30: 34.78 | H30: 619079 | I30: CLINKER
A31: 46119 | B31: CAMPANA | C31: SIDERAR | D31: 150 | H31: VACIO
A32: 46119 | B32: SIDERAR | C32: RAMALLO | D32: 10 | H32: 1063740 | I32: CORTO
A33: 46119 | B33: RAMALLO | C33: SIDERAR | D33: 10 | H33: VACIO
A34: 46119 | B34: SIDERAR | C34: RAMALLO | D34: 10 | H34: 1063806 | I34: CORTO
A35: 46119 | B35: RAMALLO | C35: SIDERAR | D35: 10 | H35: VACIO
A36: 46120 | B36: SIDERAR | C36: RAMALLO | D36: 10 | H36: 1063946 | I36: CORTO
A37: 46120 | B37: RAMALLO | C37: SIDERAR | D37: 10 | H37: VACIO
A38: 46120 | B38: SIDERAR | C38: RAMALLO | D38: 10 | H38: 1063984 | I38: CORTO
A39: 46120 | B39: RAMALLO | C39: SIDERAR | D39: 10 | H39: VACIO
A40: 46120 | B40: SIDERAR | C40: RAMALLO | D40: 10 | H40: 1064021 | I40: CORTO
A41: 46121 | B41: RAMALLO | C41: SIDERAR | D41: 10 | H41: VACIO
A42: 46121 | B42: SIDERAR | C42: RAMALLO | D42: 10 | H42: 1064167 | I42: CORTO
A43: 46121 | B43: RAMALLO | C43: ZAPALA | D43: 1470 | F43: 34.74 | H43: 1064266 | I43: LODO | K43: 2179217.6
A44: 46125 | B44: ZAPALA | C44: L. NEGRA | D44: 1060 | H44: 16405 | I44: TANDILIA | K44: 1528749.1
A45: 46127 | B45: L. NEGRA | C45: ZAPALA | D45: 1010 | F45: 34.85 | H45: 619688 | I45: CLINKER
A46: 46128 | B46: ZAPALA | C46: ALLEN | D46: 240 | H46: VACIO
A47: 46128 | B47: ALLEN | C47: L. NEGRA | D47: 820 | F47: 34 | H47: 189643 | I47: YESO LOMA
A48: 46134 | B48: L. NEGRA | C48: ZAPALA | D48: 1010 | F48: 34.78 | H48: 620092 | I48: CLINKER
A49: 46135 | B49: ZAPALA | C49: ALLEN | D49: 240 | H49: VACIO
A50: 46135 | B50: ALLEN | C50: L. NEGRA | D50: 820 | F50: 34.9 | H50: 189844 | I50: YESO LOMA
A51: 46137 | B51: L. NEGRA | C51: SAN EFRNANDO | D51: 420 | F51: 34.96 | H51: 294560 | I51: FENOMIX
A52: 46139 | B52: SAN FERNANDO | C52: IBICUY | D52: 150 | H52: VACIO
A53: 46139 | B53: IBICUY | C53: BAJO DEL TORO | D53: 1560 | H53: 123493 | I53: YPF TORO
D54: 30 A LAS 23
D56: =SUM(D3:D55) -> 9980 | F56: =AVERAGE(F3:F54) -> 34.7425 | J56: =SUM(J3:J55) -> 0 | K56: =SUM(K3:K55) -> 3707966.7
B58: -2000
B59: 315 | C59: peajes | D59: 44095
B60: -400 | C60: adelanto
B61: 160 | C61: peajes
B62: -200 | C62: ADELANTO
B63: 160 | C63: peajes
B64: 200 | C64: adelanto
B65: -200 | C65: adelanto
B66: 200 | C66: PEAJES | D66: 44137
B67: -300 | C67: adelanto | D67: 44151
B68: 515 | C68: peajes | D68: 44163
...

Sheet NOVILLO
D1: AC860OW
A2: DIA | B2: SALE DE | C2: LLEGA A | D2: KM REC | E2: TN COM 29 | F2: TN ESC 35 | G2: TN ESC 37,5 | H2: REMITO Nº | I2: MATERIAL | J2: KM VACIOS | K2: $
A25: 46113 | B25: ROSARIO | C25: IBICUY | D25: 300 | H25: VACIO
A26: 46113 | B26: IBICUY | C26: ADELA 6 | D26: 1450 | H26: 118679 | I26: ADELA YPF
A27: 46115 | B27: ADELA 6 | C27: L. NEGRA | D27: 970 | H27: VACIO
A28: 46119 | B28: L. NEGRA | C28: CAMPANA | D28: 420 | F28: 34.59 | H28: 619143 | I28: HOLCIM
A29: 46120 | B29: CAMPANA | C29: IBICUY | D29: 85 | H29: VACIO
A30: 46120 | B30: IBICUY | C30: AÑELO | D30: 1430 | H30: 119935 | I30: YPF
A31: 46122 | B31: AÑELO | C31: L. NEGRA | D31: 940 | H31: VACIO
A32: 46126 | B32: L. NEGRA | C32: ZAPALA | D32: 1010 | F32: 34.19 | H32: 619649 | I32: CLINKER
A33: 46127 | B33: ZAPALA | C33: ALLEN | D33: 230 | H33: VACIO
A34: 46128 | B34: ALLEN | C34: L. NEGRA | D34: 820 | F34: 34.8 | H34: 189593 | I34: YESO LOMA
A35: 46130 | B35: L. NEGRA | C35: ZAPALA | D35: 1010 | F35: 34.58 | H35: 619979 | I35: CLINKER
A36: 46133 | B36: ZAPALA | C36: ALLEN | D36: 240 | H36: VACIO
A37: 46134 | B37: ALLEN | C37: L. NEGRA | D37: 820 | F37: 34.1 | H37: 189808 | I37: YESO LOMA
A38: 46135 | B38: L. NEGRA | C38: SALTO | D38: 380 | H38: 767727
A39: 46136 | B39: SALTO | C39: LOMASER | D39: 200 | H39: VACIO
A40: 46136 | B40: LOMASER | C40: RAMALLO | D40: 300 | H40: 5292 | I40: PALLETS
A41: 46137 | B41: RAMALLO | C41: L. NEGRA | D41: 500 | F41: 34.88 | H41: 1067076 | I41: ESCORIA
A42: 46140 | B42: L. NEGRA | C42: RAMALLO | D42: 500 | H42: 620414
A43: 46140 | B43: RAMALLO | C43: SIDERAR | D43: 10 | H43: VACIO
A44: 46140 | B44: SIDERAR | C44: RAMALLO | D44: 10 | H44: 1067559 | I44: CORTO
A45: 46141 | B45: RAMALLO | C45: SIDERAR | D45: 10 | H45: VACIO
A46: 46141 | B46: SIDERAR | C46: RAMALLO | D46: 10 | H46: 1067641 | I46: CORTO
A47: 46141 | B47: RAMALLO | C47: L. NEGRA | D47: 500 | H47: 1067674 | I47: ESCORIA
A48: 46142 | B48: L. NEGRA | C48: CACHARI | D48: 130 | F48: ENGANCHO | G48: ACOPLADO | H48: ALBORNOZ
A49: 46142 | B49: CACHARI | C49: HINOJO | D49: 130 | H49: VACIO
D50: 30 A LAS 20
D52: =SUM(D3:D51) -> 12405 | F52: =AVERAGE(F3:F50) -> 34.523333 | J52: =SUM(J3:J51) -> 0 | K52: =SUM(K3:K51) -> 0 | L52: =+K52/D52 -> 0
B54: -2000
B55: 480
B56: -500
B57: 480 | C57: PEAJES | D57: 44105
B58: -500 | C58: ADELANTO | D58: 44105
B59: 480 | C59: PEAJES | D59: 44128
B60: -500 | C60: ADELANTO | D60: 44128
B61: 740 | C61: peajes | D61: 44184
B62: -700 | C62: ADELANTO | D62: 44184
B63: 1000 | C63: ARREGLO DE GOMA | D63: 44188
B64: -1000 | C64: ADELANTO
...

Sheet ARIAS
D1: AA244ZJ
A2: DIA | B2: SALE DE | C2: LLEGA A | D2: KM REC | E2: TN COM 29 | F2: TN ESC 35 | G2: TN ESC 37,5 | H2: REMITO Nº | I2: MATERIAL | J2: KM VACIOS | K2: $
A33: 46113 | B33: SOLA | C33: LOMASER | D33: 70 | H33: VACIO
A34: 46113 | B34: LOMASER | C34: PUNTA ALTA | D34: 610 | H34: 894728 | K34: 1076388.4
A35: 46118 | B35: PUNTA ALTA | C35: L. NEGRA | D35: 310 | H35: VACIO
A36: 46119 | B36: L. NEGRA | C36: SOLA | D36: 360 | F36: 35.05 | H36: 765047 | K36: 1174368.6
A37: 46120 | B37: SOLA | C37: ESCOBAR | D37: 70 | H37: DERIVACION
A38: 46121 | B38: ESCOBAR | C38: LOMASER | D38: 130 | H38: VACIO
A39: 46121 | B39: LOMASER | C39: RAMALLO | D39: 300 | H39: 895495
A40: 46122 | B40: RAMALLO | C40: ESCOBAR | D40: 185 | F40: 35.24 | H40: 278830 | I40: ESCORIA
A41: 46122 | B41: ESCOBAR | C41: LOMASER | D41: 130 | H41: VACIO
A42: 46122 | B42: LOMASER | C42: PUNTA ALTA | D42: 610 | H42: 895692 | K42: 1076388.4
A43: 46125 | B43: PUNTA ALTA | C43: L. NEGRA | D43: 310 | H43: VACIO
A44: 46125 | B44: L. NEGRA | C44: SOLA | D44: 360 | F44: 34.98 | H44: 766068 | K44: 1171020.9
A45: 46127 | B45: SOLA | C45: LOMASER | D45: 70 | H45: VACIO
A46: 46128 | B46: LOMASER | C46: RAMALLO | D46: 300 | F46: 35 | H46: 896493
A47: 46128 | B47: RAMALLO | C47: LOMASER | D47: 300 | F47: 35.02 | H47: 279076 | I47: ESCORIA
A48: 46139 | B48: LOMASER | C48: PUNTA ALTA | D48: 610 | H48: 896758
A49: 46131 | B49: PUNTA ALTA | C49: L. NEGRA | D49: 310 | H49: VACIO
A50: 46132 | B50: L. NEGRA | C50: SOLA | D50: 360 | F50: 34.9 | H50: 767180
A51: 46134 | B51: SOLA | C51: LOMASER | D51: 70 | H51: VACIO
A52: 46135 | B52: LOMASER | C52: RAMALLO | D52: 300 | H52: 897555
A53: 46135 | B53: RAMALLO | C53: LOMASER | D53: 300 | F53: 35.28 | H53: 279337 | I53: ESCORIA
A54: 46136 | B54: LOMASER | C54: PUNTA ALTA | D54: 610 | H54: 897821
A55: 46142 | B55: PUNTA ALTA | C55: L. NEGRA | D55: 310 | H55: VACIO
D56: LLEGO A PRINGLES
D58: =SUM(D3:D57) -> 6985 | F58: =AVERAGE(F3:F56) -> 35.067143 | J58: =SUM(J3:J57) -> 0 | K58: =SUM(K3:K57) -> 4498166.2
B60: -2000
B61: 300
B62: -300 | C62: ADELANTO | D62: 44229
B63: 300 | C63: PEAJE
B64: -300 | C64: ADELANTO
B65: 200 | C65: PEAJE | D65: 44279
B66: 300 | C66: BALANZA
B67: -500 | C67: ADELANTO
B68: 345 | C68: PEAJE | D68: 44300
B69: -400 | C69: ADELANTO
B70: 615 | C70: PEAJE | D70: 44324
B71: -600 | C71: ADELANTO
B72: 1000 | C72: gomeria | D72: 44329
...

Sheet JUAREZ
D1: NYU 936
A2: DIA | B2: SALE DE | C2: LLEGA A | D2: KM REC | E2: TN COM 29 | F2: TN ESC 35 | G2: TN ESC 37,5 | H2: REMITO Nº | I2: MATERIAL | J2: KM VACIOS | K2: $
A36: 46112 | B36: L. NEGRA | C36: SOLA | D36: 360 | G36: 37.36 | H36: 293159 | I36: PIEDRA | K36: 704281.13
A37: 46113 | B37: SOLA | C37: IBICUY | D37: 180 | H37: VACIO
A38: 46114 | B38: IBICUY | C38: AÑELO | D38: 1430 | H38: 118879 | I38: YPF
A39: 46118 | B39: AÑELO | C39: L. NEGRA | D39: 1000 | H39: VACIO
A40: 46120 | B40: L. NEGRA | C40: CAMPANA | D40: 420 | G40: 36.86 | H40: 619192 | I40: HOLCIM
A41: 46121 | B41: CAMPANA | C41: RAMALLO | D41: 170 | G41: FUE A TALLER | H41: VACIO | I41: BESTEN
A42: 46123 | B42: RAMALLO | C42: L. NEGRA | D42: 500 | G42: 35.62 | H42: 1064633 | I42: LODO
A43: 46125 | B43: L. NEGRA | C43: SANTA ROSA | D43: 450 | H43: 766112
A44: 46126 | B44: SANTA ROSA | C44: L. NEGRA | D44: 450 | H44: VACIO
A45: 46126 | B45: L. NEGRA | C45: S. FERNANDO | D45: 420 | H45: 766324
A46: 46127 | B46: S. FERNANDO | C46: IBICUY | D46: 150 | H46: VACIO
A47: 46128 | B47: IBICUY | C47: BAJO DEL TORO | D47: 1560 | H47: 121289 | I47: YPF TORO
A48: 46130 | B48: BAJO DEL TORO | C48: ALLEN | D48: 270 | H48: VACIO
A49: 46132 | B49: ALLEN | C49: L. NEGRA | D49: 820 | G49: 34.2 | H49: 189557 | I49: YESO LOMA
A50: 46134 | B50: L. NEGRA | C50: ZAPALA | D50: 1010 | G50: 36.19 | H50: 620169 | I50: CLINKER
A51: 46136 | B51: ZAPALA | C51: ALLEN | D51: 240 | H51: VACIO
A52: 46136 | B52: ALLEN | C52: L. NEGRA | D52: 820 | G52: 36.5 | H52: 189893 | I52: YESO LOMA
A53: 46139 | B53: L. NEGRA | C53: CAMPANA | D53: 420 | G53: 36.52 | H53: 620386 | I53: HOLCIM
A54: 46140 | B54: CAMPANA | C54: IBICUY | D54: 85 | H54: VACIO
A55: 46141 | B55: IBICUY | C55: BAJO DEL TORO | D55: 1520 | H55: 123675 | I55: YPF TORO
D56: 30 A LAS 21
D58: =SUM(D3:D57) -> 12275 | G58: =AVERAGE(G3:G56) -> 36.178571 | J58: =SUM(J3:J57) -> 0 | K58: =SUM(K3:K57) -> 704281.13
B60: -2000
B61: 300 | C61: 44419
B62: -300 | C62: 44419
B63: 300 | C63: PEAJES | D63: 44483
B64: -300 | C64: ADELANTO | D64: 44483
B65: -700 | C65: GOMERIA
B66: 700 | C66: ADELANTO
B67: 1000 | C67: PEAJES
B68: -1000 | C68: ADELANTO
B69: 420 | C69: BALANZA | D69: 44610
B70: -500 | C70: ADELANTO
B71: 440 | C71: peajes | D71: 44645
B72: -400 | C72: adelanto | D72: 44645
B73: 680 | C73: peajes | D73: 44676
B74: -700 | C74: ADELANTO | D74: 44676
B75: -300 | C75: ANTEC PENAL | D75: 44741
...

Sheet MEHRING
D1: NYU 936
A2: DIA | B2: SALE DE | C2: LLEGA A | D2: KM REC | E2: TN COM 29 | F2: TN ESC 35 | G2: TN ESC 37,5 | H2: REMITO Nº | I2: MATERIAL | J2: KM VACIOS | K2: $
A33: 46113 | B33: LOMASER | C33: L. NEGRA | D33: 300 | H33: VACIO
A34: 46113 | B34: L. NEGRA | C34: BAHIA BLANCA | D34: 310 | F34: 33.96 | H34: 764519
A35: 46118 | B35: BAHIA BLANCA | C35: L. NEGRA | D35: 310 | H35: VACIO
A36: 46118 | B36: L. NEGRA | C36: M. DEL PLATA | D36: 320 | F36: 33.96 | H36: 764969
A37: 46119 | B37: M. DEL PLATA | C37: L. NEGRA | D37: 320 | H37: VACIO
A38: 46120 | B38: L. NEGRA | C38: OLAVARRIA | D38: 40 | F38: 33.82 | H38: 765164 | K38: 294013.49
A39: 46120 | B39: OLAVARRIA | C39: L. NEGRA | D39: 40 | H39: VACIO
A40: 46121 | B40: L. NEGRA | C40: OLAVARRIA | D40: 40 | F40: 33.98 | H40: 765411 | K40: 295404.45
A41: 46122 | B41: OLAVARRIA | C41: L. NEGRA | D41: 40 | H41: VACIO
A42: 46122 | B42: L. NEGRA | C42: B. DE ESCOBAR | D42: 430 | F42: 34.12 | H42: 765699
A43: 46125 | B43: B. ESCOBAR | C43: LOMASER | D43: 140 | H43: VACIO
A44: 46126 | B44: LOMASER | C44: RAMALLO | D44: 300 | H44: 896108
A45: 46126 | B45: RAMALLO | C45: LOMASER | D45: 300 | H45: 278974 | I45: ESCORIA
A46: 46127 | B46: LOMASER | C46: RAMALLO | D46: 300 | H46: 896347
A47: 46127 | B47: RAMALLO | C47: LOMASER | D47: 300 | H47: 279034 | I47: ESCORIA
A48: 46127 | B48: LOMASER | C48: L. NEGRA | D48: 300 | H48: VACIO
A49: 46129 | B49: L. NEGRA | C49: B. DE ESCOBAR | D49: 430 | F49: 34.08 | H49: 766862
A50: 46132 | B50: B. ESCOBAR | C50: LOMASER | D50: 140 | H50: VACIO
A51: 46132 | B51: LOMASER | C51: DARSENA | D51: 80 | F51: 33.94 | H51: 897030
A52: 46133 | B52: DARSENA | C52: LOMASER | D52: 80 | H52: VACIO
A53: 46134 | B53: LOMASER | C53: RAMALLO | D53: 300 | H53: 897340
A54: 46134 | B54: RAMALLO | C54: LOMASER | D54: 300 | H54: 279303 | I54: ESCORIA
A55: 46136 | B55: LOMASER | C55: PUNTA ALTA | D55: 610 | F55: 35.97 | H55: 897808
A56: 46137 | B56: PUNTA ALTA | C56: L. NEGRA | D56: 310 | H56: VACIO
A57: 46137 | B57: L. NEGRA | C57: SOLA | D57: 360 | F57: 34 | H57: 768152
A58: 46139 | B58: SOLA | C58: LOMASER | D58: 70 | H58: VACIO
A59: 46140 | B59: LOMASER | C59: TORTUGUITAS | D59: 140 | F59: 33.86 | H59: 898328
A60: 46140 | B60: TORTUGUITAS | C60: LOMASER | D60: 140 | H60: VACIO
A61: 46141 | B61: LOMASER | C61: RAMALLO | D61: 300 | H61: 898631
A62: 46142 | B62: RAMALLO | C62: SOLA | D62: 240 | F62: 33.42 | H62: 279581 | I62: ESCORIA
D63: 30 A LAS 15
D65: =SUM(D3:D64) -> 7290 | F65: =AVERAGE(F3:F63) -> 34.100909 | J65: =SUM(J3:J64) -> 0 | K65: =SUM(K3:K64) -> 589417.94 | L65: =+K65/D65 -> 80.852941
B67: -2000
B68: 280 | C68: peajes | D68: 44523
B69: -300 | C69: adelanto | D69: 44523
B70: 300 | C70: BALANZA S.PEDRO | D70: 44566
B71: -300 | C71: adelanto | D71: 44566
B72: 1060 | C72: peajes | D72: 44581
...

Sheet RAMOS
D1: NYU 936
A2: DIA | B2: SALE DE | C2: LLEGA A | D2: KM REC | E2: TN COM 29 | F2: TN ESC 35 | G2: TN ESC 37,5 | H2: REMITO Nº | I2: MATERIAL | J2: KM VACIOS | K2: $
A28: 46112 | B28: ALLEN | C28: L. NEGRA | D28: 820 | F28: 35.2 | H28: 189330 | I28: YESO LOMA
A29: 46118 | B29: L. NEGRA | C29: M. DEL PLATA | D29: 320 | H29: 764961 | K29: 857189.3
A30: 46119 | B30: M. DEL PLATA | C30: L. NEGRA | D30: 320 | H30: VACIO
A31: 46120 | B31: L. NEGRA | C31: CAMPANA | D31: 420 | F31: 34.62 | H31: 619200 | I31: HOLCIM
A32: 46120 | B32: CAMPANA | C32: IBICUY | D32: 85 | H32: VACIO
A33: 46121 | B33: IBICUY | C33: BAJO DEL TORO | D33: 1570 | H33: 120071 | I33: YPF TORO 5
A34: 46123 | B34: BAJO DEL TORO | C34: L. NEGRA | D34: 1070 | H34: VACIO
A35: 46126 | B35: L. NEGRA | C35: GRAL. PICO | D35: 450 | H35: 766231
A36: 46127 | B36: GRAL. PICO | C36: L. NEGRA | D36: 450 | H36: VACIO
A37: 46128 | B37: L. NEGRA | C37: ZAPALA | D37: 1010 | F37: 34.56 | H37: 619778 | I37: CLINKER
A38: 46129 | B38: ZAPALA | C38: L. NEGRA | D38: 1060 | H38: 16415 | I38: TANDILIA
A39: 46132 | B39: L. NEGRA | C39: BERISSO | D39: 360 | F39: 34.4 | H39: 294169 | I39: PIEDRA
A40: 46133 | B40: BERISSO | C40: LOMASER | D40: 110 | H40: VACIO
A41: 46133 | B41: LOMASER | C41: ZAPALA | D41: 1300 | H41: 5279 | I41: PALLETS
A42: 46135 | B42: ZAPALA | C42: L. NEGRA | D42: 1060 | H42: 16433 | I42: TANDILIA
A43: 46136 | B43: L. NEGRA | C43: M. DEL PLATA | D43: 320 | H43: 767985
A44: 46139 | B44: M. DEL PLATA | C44: L. NEGRA | D44: 320 | H44: VACIO
A45: 46139 | B45: L. NEGRA | C45: TORCUATO | D45: 400 | F45: 34.54 | H45: 294677 | I45: PIEDRA
A46: 46140 | B46: TORCUATO | C46: IBICUY | D46: 150 | H46: VACIO
A47: 46140 | B47: IBICUY | C47: BAJO DEL TORO | D47: 1560 | H47: ???? | I47: YPF TORO
D48: 1 A LAS 4 AM
D50: =SUM(D3:D49) -> 13155 | F50: =AVERAGE(F3:F48) -> 34.664 | J50: =SUM(J3:J49) -> 0 | K50: =SUM(K3:K49) -> 857189.3 | L50: =+K50/D50 -> 65.160722
B52: -2000
B53: 220 | C53: PEAJES | D53: 44517
B54: -300 | C54: ADELANTO | D54: 44517
B55: 620 | C55: PEAJES
B56: -600 | C56: ADELANTO | D56: 44530
B57: 220 | C57: PEAJES | D57: 44558
B58: -200 | C58: ADELANTO | D58: 44558
B59: 620 | C59: PEAJES | D59: 44560
B60: -600 | C60: ADELANTO | D60: 44560
B61: 220 | C61: PEAJES | D61: 44564
B62: -200 | C62: ADELANTO
B63: 220 | C63: PEAJES | D63: 44568
B64: -220 | C64: ADELANTO | D64: 44568
B65: 420 | C65: BALANZA | D65: 44571
B66: 500 | C66: ADELANTO
B67: 620 | C67: PEAJES | D67: 44576
...

Sheet GARCIA
D1: NYU 936
A2: DIA | B2: SALE DE | C2: LLEGA A | D2: KM REC | E2: TN COM 29 | F2: TN ESC 35 | G2: TN ESC 37,5 | H2: REMITO Nº | I2: MATERIAL | J2: KM VACIOS | K2: $
A28: 46111 | B28: IBICUY | C28: ADELA 6 | D28: 1490 | H28: 118241 | I28: ADELA YPF
A29: 46114 | B29: ADELA 6 | C29: L. NEGRA | D29: 1070 | H29: VACIO
A30: 46116 | B30: L. NEGRA | C30: CAMPANA | D30: 420 | F30: 35.12 | H30: 618963 | I30: HOLCIM
A31: 46118 | B31: CAMPANA | C31: IBICUY | D31: 85 | H31: VACIO
A32: 46119 | B32: IBICUY | C32: BAJO DEL TORO | D32: 1560 | H32: 119623 | I32: YPF TORO
A33: 46122 | B33: BAJO DEL TORO | C33: L. NEGRA | D33: 1070 | H33: VACIO
A34: 46125 | B34: L. NEGRA | C34: ZAPALA | D34: 1010 | F34: 35.47 | H34: 619576 | I34: CLINKER
A35: 46127 | B35: ZAPALA | C35: ALLEN | D35: 240 | H35: VACIO
A36: 46127 | B36: ALLEN | C36: L. NEGRA | D36: 820 | F36: 29.1 | H36: 189549 | I36: YESO LOMA
A37: 46129 | B37: L. NEGRA | C37: ZAPALA | D37: 1010 | H37: 619865 | I37: CLINKER
A38: 46132 | B38: ZAPALA | C38: ALLEN | D38: 240 | H38: VACIO
A39: 46132 | B39: ALLEN | C39: L. NEGRA | D39: 820 | F39: 27.8 | H39: 189728 | I39: YESO LOMA
A40: 46136 | B40: L. NEGRA | C40: TORCUATO | D40: 400 | H40: 294489 | I40: PIEDRA
A41: 46139 | B41: TORCUATO | C41: IBICUY | D41: 150 | H41: VACIO
A42: 46139 | B42: IBICUY | C42: AÑELO | D42: 1430 | H42: 123322 | I42: YPF
A43: 46141 | B43: AÑELO | C43: L. NEGRA | D43: 940 | H43: VACIO
D44: 30 A LAS 14
D46: =SUM(D3:D45) -> 12755 | F46: =AVERAGE(F3:F44) -> 31.8725 | J46: =SUM(J3:J45) -> 0 | K46: =SUM(K3:K45) -> 0
B48: -2000
B49: 280 | C49: peajes | D49: 44550
B50: 1220 | C50: peajes | D50: 44641
B51: -1500 | C51: adelanto | D51: 44641
B52: 600 | C52: PEAJES
B53: -600 | C53: ADELANTO
B54: 560 | C54: peajes | D54: 44809
B55: -600 | C55: adelanto | D55: 44809
B56: 1360 | C56: PEAJES | D56: 44814
B57: -1400 | C57: ADELANTO
B58: 840 | C58: PEAJES | D58: 44818
B59: -800 | C59: adelanto | D59: 44818
B60: 1660 | C60: peajes | D60: 44837
B61: -1700 | C61: adelanto | D61: 44837
B62: 400 | C62: peajes | D62: 44863
B63: -400 | C63: adelanto
B64: -300 | C64: ANT. PENALES | D64: 44867
B65: 400 | C65: peajes | D65: 44868
B66: -400 | C66: adelanto | D66: 44868
B67: 800 | C67: PEAJES | D67: 44877
...

Sheet BENITEZ
D1: NYU 936
A2: DIA | B2: SALE DE | C2: LLEGA A | D2: KM REC | E2: TN COM 29 | F2: TN ESC 35 | G2: TN ESC 37,5 | H2: REMITO Nº | I2: MATERIAL | J2: KM VACIOS | K2: $
A25: 46112 | B25: LOMASER | C25: RAMALLO | D25: 300 | H25: 894559
A26: 46113 | B26: RAMALLO | C26: LOMASER | D26: 300 | F26: 36.3 | H26: 278577 | I26: ESCORIA
A27: 46116 | B27: LOMASER | C27: RAMALLO | D27: 300 | H27: 894798
A28: 46116 | B28: RAMALLO | C28: SOLA | D28: 240 | F28: 36.46 | H28: 278627 | I28: ESCORIA
A29: 46120 | B29: SOLA | C29: LOMASER | D29: 80 | H29: VACIO
A30: 46120 | B30: LOMASER | C30: BOSQUES | D30: 105 | F30: 36.38 | H30: 895238 | K30: 405399.07
A31: 46121 | B31: BOSQUES | C31: LOMASER | D31: 105 | H31: VACIO
A32: 46121 | B32: LOMASER | C32: RAMALLO | D32: 300 | H32: 895461
A33: 46122 | B33: RAMALLO | C33: LOMASER | D33: 300 | F33: 36.54 | H33: 278822 | I33: ESCORIA
A34: 46125 | B34: LOMASER | C34: DARSENA F | D34: 80 | F34: 36.09 | H34: 895964
A35: 46126 | B35: DARSENA F | C35: BARADERO | D35: 150 | H35: TALLER
A36: 46127 | B36: BARADERO | C36: LOMASER | D36: 190 | H36: VACIO
A37: 46128 | B37: LOMASER | C37: RAMALLO | D37: 300 | H37: 896497
A38: 46128 | B38: RAMALLO | C38: LOMASER | D38: 300 | F38: 36 | H38: 279084 | I38: ESCORIA
A39: 46132 | B39: LOMASER | C39: RAMALLO | D39: 300 | H39: 896961
A40: 46132 | B40: RAMALLO | C40: LOMASER | D40: 300 | F40: 36.28 | H40: 279210 | I40: ESCORIA
A41: 46132 | B41: LOMASER | C41: L. NEGRA | D41: 300 | H41: VACIO
A42: 46135 | B42: L. NEGRA | C42: B. DE ESCOBAR | D42: 430 | F42: 36.78 | H42: 767731
A43: 46136 | B43: B. ESCOBAR | C43: LOMASER | D43: 140 | H43: VACIO
A44: 46139 | B44: LOMASER | C44: RAMALLO | D44: 300 | H44: 898075
A45: 46139 | B45: RAMALLO | C45: URIBURU | D45: 80 | F45: 36.38 | H45: 279455
A46: 46140 | B46: URIBURU | C46: RAMALLO | D46: 80 | H46: VACIO
A47: 46140 | B47: RAMALLO | C47: LOMASER | D47: 300 | F47: 36.52 | H47: 279492 | I47: ESCORIA
A48: 46141 | B48: LOMASER | C48: RAMALLO | D48: 300 | F48: 36.26 | H48: 898492
A49: 46141 | B49: RAMALLO | C49: LOMASER | D49: 300 | F49: 36.42 | H49: 279561 | I49: ESCORIA
A50: 46142 | B50: LOMASER | C50: TORCUATO | D50: 140 | F50: 36.2 | H50: 898784
A51: 46142 | B51: TORCUATO | C51: LOMASER | D51: 140 | H51: VACIO
D52: 30A LAS 20
D54: =SUM(D3:D53) -> 6160 | F54: =AVERAGE(F3:F52) -> 36.354615 | J54: =SUM(J3:J53) -> 0 | K54: =SUM(K3:K53) -> 405399.07
B56: -2000
B57: 680 | C57: peajes | D57: 44629
B58: -700 | C58: adelanto
B59: 420 | C59: peajes | D59: 44635
B60: -400 | C60: adelanto | D60: 44635
B61: 680 | C61: PEAJES | D61: 44643
B62: -700 | C62: ADELANTO
B63: 680 | C63: peajes | D63: 44699
B64: -700 | C64: adelanto
...

Sheet CANCELA
A2: DIA | B2: SALE DE | C2: LLEGA A | D2: KM REC | E2: TN COM 29 | F2: TN ESC 35 | G2: TN ESC 37,5 | H2: REMITO Nº | I2: MATERIAL | J2: KM VACIOS | K2: $
A30: 46112 | B30: IBICUY | C30: AÑELO | D30: 1430 | H30: 118339 | I30: YPF
A31: 46114 | B31: AÑELO | C31: L. NEGRA | D31: 940 | H31: VACIO
A32: 46116 | B32: L. NEGRA | C32: CAMPANA | D32: 420 | F32: 34.35 | H32: 618966 | I32: HOLCIM
A33: 46119 | B33: CAMPANA | C33: IBICUY | D33: 85 | H33: VACIO
A34: 46120 | B34: IBICUY | C34: BAJO DEL TORO | D34: 1560 | H34: 119854 | I34: YPF TORO
A35: 46122 | B35: BAJO DEL TORO | C35: L. NEGRA | D35: 1070 | H35: VACIO
A36: 46125 | B36: L. NEGRA | C36: CAMPANA | D36: 430 | H36: 293735 | I36: PIEDRA
A37: 46126 | B37: CAMPANA | C37: IBICUY | D37: 100 | H37: VACIO
A38: 46126 | B38: IBICUY | C38: BAJO DEL TORO | D38: 1470 | H38: 121071 | I38: YPF TORO 5
A39: 46128 | B39: BAJO DEL TORO | C39: L. NEGRA | D39: 1070 | H39: VACIO
A40: 46133 | B40: L. NEGRA | C40: J. C. PAZ | D40: 390 | H40: 767372
A41: 46134 | B41: J. C. PAZ | C41: IBICUY | D41: 170 | H41: VACIO
A42: 46135 | B42: IBICUY | C42: BAJO DEL TORO | D42: 1560 | H42: 122522 | I42: YPF TORO
A43: 46137 | B43: BAJO DEL TORO | C43: L. NEGRA | D43: 1070 | H43: VACIO
A44: 46139 | B44: L. NEGRA | C44: CAMPANA | D44: 430 | F44: 34.74 | H44: 294667 | I44: PIEDRA
A45: 46140 | B45: CAMPANA | C45: IBICUY | D45: 100 | H45: VACIO
A46: 46140 | B46: IBICUY | C46: AÑELO | D46: 1430 | H46: 123588 | I46: YPF
D47: 30 A LAS 23,59
D49: =SUM(D3:D48) -> 13725 | F49: =AVERAGE(F3:F47) -> 34.545 | J49: =SUM(J3:J48) -> 0 | K49: =SUM(K3:K48) -> 0
B51: -2000 | C51: 44634
B52: 1350 | C52: PEAJES | D52: 44643
B53: -1400 | C53: ADELANTO
B54: 800 | C54: peajes | D54: 44656
B55: -800 | C55: ADELANTO | D55: 44656
B56: 2400 | C56: GOMERIA
B57: -2400 | C57: ADELANTO
B58: 560 | C58: PEAJES | D58: 44714
B59: -600 | C59: ADELANTO
B60: 280 | C60: PEAJES | D60: 44716
B61: -200 | C61: ADELANTO
B62: 680 | C62: PEAJES | D62: 44735
B63: -700 | C63: ADELANTO
B64: 480 | C64: PEAJES | D64: 44750
B65: -500 | C65: ADELANTO | D65: 44750
B66: 3080 | C66: GOMERIA
B67: -3070 | C67: ADELANTO
B68: 480 | C68: PEAJES | D68: 44820
B69: -500 | C69: ADELANTO
B70: 1500 | C70: gomeria
...

Sheet COSENTINO
D1: NYU 936
A2: DIA | B2: SALE DE | C2: LLEGA A | D2: KM REC | E2: TN COM 29 | F2: TN ESC 35 | G2: TN ESC 37,5 | H2: REMITO Nº | I2: MATERIAL | J2: KM VACIOS | K2: $
A27: 46116 | B27: L. NEGRA | C27: CAMPANA | D27: 420 | F27: 36.07 | H27: 618981 | I27: HOLCIM
A28: 46118 | B28: CAMPANA | C28: IBICUY | D28: 85 | H28: VACIO
A29: 46119 | B29: IBICUY | C29: AÑELO | D29: 1430 | H29: 119679 | I29: YPF
A30: 46121 | B30: AÑELO | C30: L. NEGRA | D30: 940 | H30: VACIO
A31: 46123 | B31: L. NEGRA | C31: CASEROS | D31: 380 | F31: 36 | H31: 2701178 | I31: TRAMONTANA | K31: 738000
A32: 46125 | B32: CASEROS | C32: LOMASER | D32: 130 | H32: VACIO
A33: 46125 | B33: LOMASER | C33: ROSARIO | D33: 340 | H33: 895970
A34: 46126 | B34: ROSARIO | C34: L. NEGRA | D34: 550 | H34: PALLETS | I34: LOS PAGARON | K34: 370454.21
A35: 46127 | B35: L. NEGRA | C35: ZAPALA | D35: 1010 | F35: 36.36 | H35: 619730 | I35: CLINKER
A36: 46128 | B36: ZAPALA | C36: ALLEN | D36: 240 | H36: VACIO
A37: 46128 | B37: ALLEN | C37: L. NEGRA | D37: 820 | F37: 32.7 | H37: 189647 | I37: YESO LOMA
A38: 46133 | B38: L. NEGRA | C38: ZAPALA | D38: 1010 | F38: 36.51 | H38: 620076 | I38: CLINKER
A39: 46134 | B39: ZAPALA | C39: ALLEN | D39: 240 | H39: VACIO
A40: 46135 | B40: ALLEN | C40: L. NEGRA | D40: 820 | F40: 35.7 | H40: 189829 | I40: YESO LOMA
A41: 46136 | B41: L. NEGRA | C41: CAMPANA | D41: 430 | H41: 293735 | I41: PIEDRA
A42: 46139 | B42: CAMPANA | C42: IBICUY | D42: 100 | H42: VACIO
A43: 46139 | B43: IBICUY | C43: BAJO DEL TORO | D43: 1560 | H43: ???? | I43: YPF TORO
D44: 30 A LAS 15
J45: =SUM(J3:J44) -> 0
D46: =SUM(D3:D45) -> 10505 | G46: =AVERAGE(G3:G44) -> #DIV/0! | K46: =SUM(K3:K45) -> 1108454.2
B49: -2000 | C49: ADELANTO
